<?xml version="1.0" encoding="utf-8"?>
    <robot xmlns:xacro="https://ros.org/wiki/xacro" name="azure_sensor">

        <xacro:property name="M_PI" value="3.1415926535897931" />

        <xacro:macro name="rail" params="prefix">

            <link name="${prefix}rail">
                <visual>
                    <origin xyz="0 0 0" rpy="0 ${M_PI/2} 0" />
                    <geometry>
                        <cylinder length="3" radius="0.05"/>
                    </geometry>
                    <material name="">
                        <color rgba="1.0 1.0 1.0 1.0"/>
                    </material>
                </visual>
                <collision>
                    <origin xyz="0 0 0" rpy="0 ${M_PI/2} 0" />
                    <geometry>
                        <cylinder length="3" radius="0.05"/>
                    </geometry>

                </collision>
            </link>



            <joint name="${prefix}axis1_joint" type="prismatic">
                <parent link="${prefix}rail"/>
                <child link="${prefix}axis1"/>
                <!-- Here we enter the joint position just defined before -->
                <origin xyz="0 0 0.1" rpy="0 0 0"/>
                <!-- Here we define the axis along which the geometry is moved -->
                <axis xyz="1 0 0"/>
                <!-- Here we define the joint's upper and lower limits -->
                <limit effort="1000.0" lower="-1.0" upper="1.0" velocity="0.5"/>
            </joint>

            <link name="${prefix}axis1">
                <visual>
                    <geometry>
                        <box size=".4 0.4 0.1"/>
                    </geometry>
                    <material name="">
                        <color rgba="1.0 1.0 1.0 1.0"/>
                    </material>
                </visual>
                <collision>
                    <geometry>
                        <box size=".4 0.4 0.1"/>>
                    </geometry>
                </collision>
            </link>



        </xacro:macro>
    </robot>